<?xml version="1.0" ?>
<robot name="mobile_robo" xmlns:xacro="http://www.ros.org/wiki/xacro">

<xacro:include filename="$(find mobile_robo_description)/urdf/materials.xacro" />
<xacro:include filename="$(find mobile_robo_description)/urdf/mobile_robo.trans" />
<xacro:include filename="$(find mobile_robo_description)/urdf/mobile_robo.gazebo" />
<link name="base_link">
  <inertial>
    <origin rpy="0 0 0" xyz="0.0038775828308717252 -1.6665797136639413e-17 0.052918293473760994"/>
    <mass value="2.3138752403503777"/>
    <inertia ixx="0.007906" ixy="-0.0" ixz="-0.000337" iyy="0.008397" iyz="-0.0" izz="0.014792"/>
  </inertial>
  <visual>
    <origin rpy="0 0 0" xyz="0 0 0"/>
    <geometry>
      <mesh filename="package://mobile_robo_description/meshes/base_link.stl" scale="0.001 0.001 0.001"/>
    </geometry>
    <material name="silver"/>
  </visual>
  <collision>
    <origin rpy="0 0 0" xyz="0 0 0"/>
    <geometry>
      <mesh filename="package://mobile_robo_description/meshes/base_link.stl" scale="0.001 0.001 0.001"/>
    </geometry>
  </collision>
</link>

<link name="right_wheel_1">
  <inertial>
    <origin rpy="0 0 0" xyz="-5.790023100122029e-18 -0.012499999999999997 0.0"/>
    <mass value="0.1826050729899067"/>
    <inertia ixx="0.000124" ixy="-0.0" ixz="0.0" iyy="0.000228" iyz="0.0" izz="0.000124"/>
  </inertial>
  <visual>
    <origin rpy="0 0 0" xyz="-0.0 0.1 -0.05"/>
    <geometry>
      <mesh filename="package://mobile_robo_description/meshes/right_wheel_1.stl" scale="0.001 0.001 0.001"/>
    </geometry>
    <material name="silver"/>
  </visual>
  <collision>
    <origin rpy="0 0 0" xyz="-0.0 0.1 -0.05"/>
    <geometry>
      <mesh filename="package://mobile_robo_description/meshes/right_wheel_1.stl" scale="0.001 0.001 0.001"/>
    </geometry>
  </collision>
</link>

<link name="left_wheel_1">
  <inertial>
    <origin rpy="0 0 0" xyz="-5.790023100122029e-18 0.012499999999999997 0.0"/>
    <mass value="0.1826050729899067"/>
    <inertia ixx="0.000124" ixy="0.0" ixz="0.0" iyy="0.000228" iyz="-0.0" izz="0.000124"/>
  </inertial>
  <visual>
    <origin rpy="0 0 0" xyz="-0.0 -0.1 -0.05"/>
    <geometry>
      <mesh filename="package://mobile_robo_description/meshes/left_wheel_1.stl" scale="0.001 0.001 0.001"/>
    </geometry>
    <material name="silver"/>
  </visual>
  <collision>
    <origin rpy="0 0 0" xyz="-0.0 -0.1 -0.05"/>
    <geometry>
      <mesh filename="package://mobile_robo_description/meshes/left_wheel_1.stl" scale="0.001 0.001 0.001"/>
    </geometry>
  </collision>
</link>

<link name="lidar_1">
  <inertial>
    <origin rpy="0 0 0" xyz="0.0 5.584513020951031e-18 0.012499999999999997"/>
    <mass value="0.10789485809488784"/>
    <inertia ixx="4.1e-05" ixy="0.0" ixz="0.0" iyy="4.1e-05" iyz="-0.0" izz="7e-05"/>
  </inertial>
  <visual>
    <origin rpy="0 0 0" xyz="-0.05 -0.0 -0.11"/>
    <geometry>
      <mesh filename="package://mobile_robo_description/meshes/lidar_1.stl" scale="0.001 0.001 0.001"/>
    </geometry>
    <material name="silver"/>
  </visual>
  <collision>
    <origin rpy="0 0 0" xyz="-0.05 -0.0 -0.11"/>
    <geometry>
      <mesh filename="package://mobile_robo_description/meshes/lidar_1.stl" scale="0.001 0.001 0.001"/>
    </geometry>
  </collision>
</link>

<joint name="Rev1" type="continuous">
  <origin rpy="0 0 0" xyz="0.0 -0.1 0.05"/>
  <parent link="base_link"/>
  <child link="right_wheel_1"/>
  <axis xyz="0.0 -1.0 0.0"/>
</joint>

<joint name="Rev2" type="continuous">
  <origin rpy="0 0 0" xyz="0.0 0.1 0.05"/>
  <parent link="base_link"/>
  <child link="left_wheel_1"/>
  <axis xyz="0.0 1.0 0.0"/>
</joint>

<joint name="Rigid3" type="fixed">
  <origin rpy="0 0 0" xyz="0.05 0.0 0.11"/>
  <parent link="base_link"/>
  <child link="lidar_1"/>
</joint>

</robot>
